Workbook

Sheet ① 표지·심의결과
B2: Pre-VRB 공통시트 V1.1 [배포용 템플릿]
B3: VRB(Value & Verification Review Board) 상정 前 부문 공통 사전검토 양식
B4: 노란 셀만 입력하십시오. 회색 셀은 다른 시트 입력값으로 자동 계산됩니다.
B6: 1. 제안 개요 [입력: 사업부(영업팀, BD팀)]
B7: 과제/제안명 | C7: AI 인프라 및 생성형 AI 구축 사업 | D7: 고객/발주처 | E7: 신용보증재단중앙회 (발주부서: AI디지털전환부)
B8: 사업 유형 | C8: 공공 SI — 패키지SW 도입 및 커스터마이징 | D8: 발주 방식 | E8: 경쟁입찰 / 협상에의한계약
B9: 사업예산(추정, 원) | C9: 617500000 | D9: 사업기간 | E9: 계약체결일로부터7개월
B10: 공고일 | C10: 2026-10-00 | D10: 제안 질의 마감일 | E10: 공고문 미명시 — 확인 필요
B11: 입찰참가신청 마감 | C11: 2026-10-00 (0) 00:00 | D11: 제안서 제출 마감(D-day) | E11: 2026-10-00 (0) 00:00
B12: 낙찰자 결정방식 | C12: 협상에의한계약(기술능력평가분야배점한도의 85%이상인 자) | D12: 기술:가격 배점 | E12: 기술 90 : 가격 10
B13: 영업 담당 | C13: AX서비스사업부 AX서비스영업팀 김산 이사대우 | D13: 사업부 담당
B14: 연구소 담당 | D14: PMO 담당 | E14: AI사업부문 사업관리그룹 송승현 부장 / 송인성 부장
B15: 전략적 가치(상/중/하) | C15: 중 | D15: 판단 사유 | E15: 주사업자 사업 참여나 고객과 사전에 과업에 대한 범위가 조정 되었고, GPU 서버 납기로 개발이 제한됨
B17: 2. 게이트 판정 요약 [자동 집계]
B18: 게이트 | C18: 판정 지표 | D18: 값 | E18: 임계 기준 | F18: 판정 | G18: 비고
B19: Gate 0 적격성 | C19: 필수 자격요건 미충족 건수 | D19: ='② 입찰 적격성'!D5 -> 0 | E19: 0 건 | F19: =IF(COUNTA('② 입찰 적격성'!D8:D60)=0,"미산정",IF(D19=0,"통과","불참")) -> 미산정 | G19: 1건이라도 미충족 시 참여 불가
B20: Gate 1 기술 실현성 | C20: 불가(X) 판정 건수 | D20: =COUNTIF('③ 요구사항 검토'!O6:O300,"X") -> 0 | E20: 0 건 | F20: =IF($C$28=0,"미산정",IF(D20=0,"통과","조건부")) -> 통과 | G20: X 1건 이상 시 대안 확보 여부 확인
C21: 조건부(△) 비율 | D21: =IFERROR(COUNTIF('③ 요구사항 검토'!O6:O300,"△")/MAX(1,COUNTA('③ 요구사항 검토'!C6:C300)),0) -> 0 | E21: 40% 이하 | F21: =IF($C$28=0,"미산정",IF(D21<=0.4,"통과","주의")) -> 통과 | G21: 조건부 비율이 높을수록 범위 불확실성 큼
B22: Gate 2 사업성 | C22: 예상 이익률 | D22: ='⑥ 손익 시나리오'!D33 -> 0 | E22: 15% 이상 | F22: =IF('⑥ 손익 시나리오'!$D$10=0,"미산정",IF(D22>=0.15,"통과",IF(D22>=0.05,"조건부","불참"))) -> 미산정 | G22: 15% 이상 통과 / 5~15% 조건부 / 5% 미만 불참 권고
C23: 미반영 원가 반영 후 이익률 | D23: ='⑥ 손익 시나리오'!D35 -> 0 | E23: 5% 이상 | F23: =IF('⑥ 손익 시나리오'!$D$10=0,"미산정",IF(D23>=0.05,"통과","주의")) -> 미산정 | G23: 미반영 원가 최대치 반영 기준
B24: Gate 3 리스크 | C24: 리스크 등급 [최상] 건수 | D24: =COUNTIF('④ 리스크 및 고려사항'!H:H,"최상") -> 0 | E24: 3건 이하 | F24: =IF(COUNTA('④ 리스크 및 고려사항'!C5:C54)=0,"미산정",IF(D24<=3,"통과","주의")) -> 미산정 | G24: 최상 리스크는 대응방안 필수 기재
C25: 미해결 확인사항 [최우선] 건수 | D25: =COUNTIFS('⑤ 확인사항·질의'!G:G,"최우선",'⑤ 확인사항·질의'!H:H,"<>완료") -> 0 | E25: 0 건 | F25: =IF(COUNTA('⑤ 확인사항·질의'!C5:C54)=0,"미산정",IF(D25=0,"통과","보류")) -> 미산정 | G25: 최우선 항목 미회신 시 제안 리스크 과다
B27: 3. 요구사항 검토 요약 [자동 집계]
B28: 요구사항 수 (고유 ID) | C28: =IFERROR(SUMPRODUCT(('③ 요구사항 검토'!C6:C300<>"")/COUNTIF('③ 요구사항 검토'!C6:C300,'③ 요구사항 검토'!C6:C300&"")),0) -> 62 | D28: 세부항목 수 | E28: =COUNTA('③ 요구사항 검토'!C6:C300) -> 261
B29: 제품 대응 (F1+F2) 건수 | C29: =COUNTIF('③ 요구사항 검토'!J6:J300,"F1*")+COUNTIF('③ 요구사항 검토'!J6:J300,"F2*") -> 0 | D29: 제품 추가개발 (F3) 건수 | E29: =COUNTIF('③ 요구사항 검토'!J6:J300,"F3*") -> 0
B30: 제품 미지원 (F4·SI 대상) 건수 | C30: =COUNTIF('③ 요구사항 검토'!J6:J300,"F4*") -> 0 | D30: 가능여부 O / △ / X | E30: =COUNTIF('③ 요구사항 검토'!O6:O300,"O")&" / "&COUNTIF('③ 요구사항 검토'!O6:O300,"△")&" / "&COUNTIF('③ 요구사항 검토'!O6:O300,"X") -> 0 / 0 / 0
B32: 4. 부문별 공수 및 원가 [③ 요구사항 검토 / ⑥ 손익 시나리오 연동]
B33: 부문 | C33: 공수(M/M) | D33: 비중 | E33: 월 단가(원) | F33: 인건비(원) | G33: 비고
B34: AI사업부문 - 수행(개발) | C34: =SUM('③ 요구사항 검토'!T6:T300) -> 0 | D34: =IFERROR(C34/$C$38,0) -> 0 | F34: =C34*E34 -> 0 | G34: 제안 활동 공수 (부문 방침에 따라 산정 여부 결정)
B35: 인공지능연구소(R&D) | C35: =SUM('③ 요구사항 검토'!L6:L300) -> 0 | D35: =IFERROR(C35/$C$38,0) -> 0 | F35: =C35*E35 -> 0 | G35: 제품 추가개발 공수 (③시트 Fit 판정 F3 항목)
B36: PM · PMO | C36: =SUM('③ 요구사항 검토'!W6:W300) -> 0 | D36: =IFERROR(C36/$C$38,0) -> 0 | F36: =C36*E36 -> 0 | G36: PM 주관 산정 / PMO 가이드·검증 — 부장 단가 적용
B37: 외주 / 협력사 | C37: =SUM('③ 요구사항 검토'!U6:U300) -> 0 | D37: =IFERROR(C37/$C$38,0) -> 0 | F37: =C37*E37 -> 0 | G37: 수행부서 가용 인력 부족분을 협력업체 외주용역으로 구성
B38: 합 계 (확정) | C38: =SUM(C34:C37) -> 0 | D38: =IFERROR(SUM(D34:D37),0) -> 0 | F38: =SUM(F34:F37) -> 0
B39: 외주 비중 (금액 기준) | C39: =IFERROR(F37/F38,0) -> 0 | D39: 「소프트웨어 진흥법」 제51조: 물품(상용SW) 제외 SW사업금액의 50% 초과 불가 / 10% 초과 시 공동수급체 구성 원칙(미구성 시 사유 제시) / 하도급계획 적정성 평가와 연동
B40: [참고] 영업(BD) 사전산정 | C40: =SUM('③ 요구사항 검토'!H6:H300) -> 0 | D40: 확정 대비 증감 | E40: =C38-C40 -> 0 | F40: =IFERROR(E40/C40,0) -> 0 | G40: 영업(BD) 사전산정치는 비교·검증용이며 원가 합계에는 합산하지 않습니다
B42: 5. VRB 최종 결정 및 조건 [입력: VRB / 심의위원회 의결]
B43: VRB 최종 결정 | D43: 결정일
B44: 의장 / 참석자 | D44: 차기 검토 시점
B45: 결정 조건 및 단서
B48: 미결 항목 · 후속 Action
...

Sheet ② 입찰 적격성
B2: Gate 0 — 입찰 적격성 체크리스트 [입력: 사업부(BD팀) · 확인: 사업부(영업팀 및 기획팀) / AI사업부문 PM및PMO]
B3: ★ 기술·사업성 검토에 앞서 '참여 가능 여부' 자체를 먼저 판정합니다. 필수 항목이 1건이라도 미충족이면 이후 검토는 진행하지 않습니다.
C5: 필수 자격요건 미충족 건수 → | D5: =COUNTIFS(B8:B60,"필수",D8:D60,"미충족") -> 0
A7: No. | B7: 구분 | C7: 확인 항목 | D7: 충족 여부 | E7: 확인자 | F7: 근거 / 비고
A8: 1 | B8: 필수 | C8: 입찰참가자격 — 사업자 등록·신고 요건 충족 (예: SW사업자 신고, 직접생산확인증명서, 중소기업확인서)
A9: 2 | B9: 필수 | C9: 기업 규모 제한 해당 여부 (대기업·중견기업 참여 제한, 상호출자제한기업집단 등)
A10: 3 | B10: 필수 | C10: 부정당업자 입찰참가자격 제한 이력 없음
A11: 4 | B11: 필수 | C11: 직접생산확인 세부품명 일치 여부
A12: 5 | B12: 필수 | C12: 제안 마감일까지 제안서 작성 가능한 물리적 일정 확보
A13: 6 | B13: 필수 | C13: 수행 가능한 핵심 인력(PM·기술) 확보 가능 여부
A14: 7 | B14: 검토 | C14: 공동수급 / 하도급 허용 여부 및 지분·비율 제한
A15: 8 | B15: 검토 | C15: 지식재산권 귀속 조건 (단독 / 공동 / 발주처 귀속) — 제품 자산 보호 가능 여부
A16: 9 | B16: 검토 | C16: 하자보수 기간·보증금율 및 무상 유지보수 요구 범위
A17: 10 | B17: 검토 | C17: 작업장소 요건 (상주 / 원격지 개발 가능 여부, 비용 부담 주체)
A18: 11 | B18: 검토 | C18: 성능·품질 목표치의 검증 방식 및 미달 시 책임 조항
A19: 12 | B19: 검토 | C19: 상용SW·HW 직접구매(분리발주) 대상 여부
... A22: 15 | B22: 검토 | C22: 기존 사업자·경쟁사 대비 레퍼런스 우위 여부

Sheet ③ 요구사항 검토
A1: 요구사항 검토 공통시트 [부문별 담당 컬럼만 입력] | T1: =SUM(T6:T300) -> 0
A2: 작성 순서 ①영업(BD): 제안요청서 원문을 단락 단위로 분해하여 전사하고 사전산정 공수 기재 → ②인공지능연구소: 제품 적합도(Fit) 판정 및 제품 추가개발 공수 → ③AI사업부문: 개발 구분·가능여부·공수 산정 → ④PM(PMO 지원): 리스크·확인사항 연결 및 종합의견
A3: 입력 담당 색상 ▪영업(BD)=연두 ▪인공지능연구소=파랑 ▪AI사업부문=주황 ▪PM·PMO=보라 ▪자동계산=회색 | 한 요구사항에 세부항목이 여러 개면 행을 나누어 기재하고 요구사항 ID·요구사항명은 반복 기재합니다 | ★영업(BD) 사전산정 공수는 비교·검증용이며 확정 공수 합계에는 합산하지 않습니다
A4: 자동 | B4: 영업 | C4: 영업 | D4: 영업 | E4: 영업 | F4: 영업 | G4: 영업 | H4: 영업 | I4: 연구소 | J4: 연구소 | K4: 연구소 | L4: 연구소 | M4: 연구소 | N4: AI사업부문 | O4: AI사업부문 | P4: AI사업부문 | Q4: AI사업부문 | R4: Konan AI Agent | T4: AI사업부문 | U4: AI사업부문 | V4: AI사업부문 | W4: PM·PMO | X4: 자동 | Y4: 자동 | Z4: PM·PMO | AA4: PM·PMO | AB4: PM·PMO | AC4: PM·PMO
A5: No. | B5: 요구사항 대분류 | C5: 요구사항 ID | D5: 요구사항명 | E5: 세부 항목 No. | F5: 상세 내용 (제안요청서 단락 원문) | G5: 우선 순위 | H5: 비고 | I5: 담당 그룹 | J5: 제품 적합도 (Fit) | K5: Fit 판정 근거 | L5: 공수 연구소 (제품 추가개발) | M5: 제품 반영 계획 | N5: 개발 구분 | O5: 가능 여부 | P5: 난이도 | Q5: 공수 산정 근거 | R5: 제공/미제공 | S5: 부가설명 | T5: 공수 AI사업부문 (수행·개발) | U5: 공수 외주·협력사 | V5: 조달 구분 | W5: 공수 PM | X5: 공수 합계 (확정) | Y5: BD 사전산정 대비 증감 | Z5: 리스크 ID | AA5: 확인사항 ID | AB5: PM·PMO 종합의견 | AC5: 비고
A6: =IF(C6="","",ROW()-5) -> 1 | B6: 시스템·기능 | C6: SFR-001 | D6: AI Core 고도화 | E6: 1 | F6: ◦ 기존 운영 모델의 성능 및 업무 적합성을 분석하고, 필요 시 AI 모델의 교체·적용을 통해 추론 및 응답 생성 역량을 고도화하여야 함 | X6: =IF(C6="","",SUM(L6,T6,U6,W6)) -> 0 | Y6: =IF(OR(C6="",H6=""),"",X6-H6)
A7: =IF(C7="","",ROW()-5) -> 2 | B7: 시스템·기능 | C7: SFR-001 | D7: AI Core 고도화 | E7: 2 | F7: ◦ 복합 질의 및 다단계 업무처리가 필요한 경우, 질의를 단계적으로 분석·처리할 수 있는 추론 기능을 제공하여야 함 | X7: =IF(C7="","",SUM(L7,T7,U7,W7)) -> 0 | Y7: =IF(OR(C7="",H7=""),"",X7-H7)
A8: =IF(C8="","",ROW()-5) -> 3 | B8: 시스템·기능 | C8: SFR-001 | D8: AI Core 고도화 | E8: 3 | F8: ◦ 사용자 질의의 의도, 대화 맥락 및 업무 맥락을 고려한 응답 생성 기능을 제공하여야 함 | X8: =IF(C8="","",SUM(L8,T8,U8,W8)) -> 0 | Y8: =IF(OR(C8="",H8=""),"",X8-H8)
A9: =IF(C9="","",ROW()-5) -> 4 | B9: 시스템·기능 | C9: SFR-001 | D9: AI Core 고도화 | E9: 4 | F9: ◦ 사실성 및 근거성이 요구되는 업무에 대해서는 부정확하거나 근거 없는 응답을 최소화할 수 있도록 적절한 통제·검증 기능을 적용하여야 함 | X9: =IF(C9="","",SUM(L9,T9,U9,W9)) -> 0 | Y9: =IF(OR(C9="",H9=""),"",X9-H9)
A10: =IF(C10="","",ROW()-5) -> 5 | B10: 시스템·기능 | C10: SFR-001 | D10: AI Core 고도화 | E10: 5 | F10: ◦ 제안사는 기존 운영 모델과 신규 적용 모델에 대한 성능 비교·분석 결과를 제시하여야 하며 모델 적용에 따른 서비스 품질 향상 효과를 제시하여야 함 | X10: =IF(C10="","",SUM(L10,T10,U10,W10)) -> 0 | Y10: =IF(OR(C10="",H10=""),"",X10-H10)
A11: =IF(C11="","",ROW()-5) -> 6 | B11: 시스템·기능 | C11: SFR-002 | D11: AI Knowledge 고도화 | E11: 1 | F11: ◦ 현재 운영 중인 RAG 기반 지식검색 체계의 데이터 처리·색인·검색 및 답변 생성 과정을 분석하고 검색 정확도 및 답변 품질 향상을 위한 개선방안을 제시·적용하여야 함 | X11: =IF(C11="","",SUM(L11,T11,U11,W11)) -> 0 | Y11: =IF(OR(C11="",H11=""),"",X11-H11)
A12: =IF(C12="","",ROW()-5) -> 7 | B12: 시스템·기능 | C12: SFR-002 | D12: AI Knowledge 고도화 | E12: 2 | F12: ◦ 업무 및 데이터 특성을 고려하여 기존 RAG의 개선·재구성 또는 신규 RAG의 추가 등 적정한 지식검색 방안을 제시·적용하여야 함 | X12: =IF(C12="","",SUM(L12,T12,U12,W12)) -> 0 | Y12: =IF(OR(C12="",H12=""),"",X12-H12)
A13: =IF(C13="","",ROW()-5) -> 8 | B13: 시스템·기능 | C13: SFR-002 | D13: AI Knowledge 고도화 | E13: 3 | F13: ◦ 사용자가 업무 목적에 따라 검색·답변에 활용한 지식 및 데이터의 참조범위를 설정·선택할 수 있도록 관련 기능을 고도화하여야 함 | X13: =IF(C13="","",SUM(L13,T13,U13,W13)) -> 0 | Y13: =IF(OR(C13="",H13=""),"",X13-H13)
A14: =IF(C14="","",ROW()-5) -> 9 | B14: 시스템·기능 | C14: SFR-002 | D14: AI Knowledge 고도화 | E14: 4 | F14: ◦ 검색 결과의 메타데이터 및 원문 연계를 통해 생성된 답변의 근거와 출처를 확인할 수 있도록 관련 기능을 고도화하여야 함 | X14: =IF(C14="","",SUM(L14,T14,U14,W14)) -> 0 | Y14: =IF(OR(C14="",H14=""),"",X14-H14)
A15: =IF(C15="","",ROW()-5) -> 10 | B15: 시스템·기능 | C15: SFR-002 | D15: AI Knowledge 고도화 | E15: 5 | F15: ◦ 사용자 질의와 검색 결과를 기반으로 연관 정보 탐색 및 후속 질의가 가능한 대화형 지식탐색 기능을 고도화하여야 함 | X15: =IF(C15="","",SUM(L15,T15,U15,W15)) -> 0 | Y15: =IF(OR(C15="",H15=""),"",X15-H15)
A16: =IF(C16="","",ROW()-5) -> 11 | B16: 시스템·기능 | C16: SFR-003 | D16: AI 실행도구 연계체계 구축 | E16: 1 | F16: ◦ 생성형 AI 및 AI Agent가 시스템, API 및 다양한 업무도구를 연계·활용할 수 있도록 확장 가능한 실행도구 연계체계를 구성하여야 함 | X16: =IF(C16="","",SUM(L16,T16,U16,W16)) -> 0 | Y16: =IF(OR(C16="",H16=""),"",X16-H16)
A17: =IF(C17="","",ROW()-5) -> 12 | B17: 시스템·기능 | C17: SFR-003 | D17: AI 실행도구 연계체계 구축 | E17: 2 | F17: ◦ 다양한 MCP 기반 도구를 통합적으로 연계·관리할 수 있도록 MCP Gateway를 구축하여야 함 | X17: =IF(C17="","",SUM(L17,T17,U17,W17)) -> 0 | Y17: =IF(OR(C17="",H17=""),"",X17-H17)
... A266: =IF(C266="","",ROW()-5) -> 261 | B266: 기타 | C266: AIG-005 | D266: AI 안전성 확보 | E266: 4 | F266: ◦ 시스템은 AI 서비스의 안전성과 신뢰성 확보를 위한 보호조치를 적용하여야 함 | X266: =IF(C266="","",SUM(L266,T266,U266,W266)) -> 0 | Y266: =IF(OR(C266="",H266=""),"",X266-H266)
A267: =IF(C267="","",ROW()-5) | X267: =IF(C267="","",SUM(L267,T267,U267,W267)) | Y267: =IF(OR(C267="",H267=""),"",X267-H267)
A268: =IF(C268="","",ROW()-5) | X268: =IF(C268="","",SUM(L268,T268,U268,W268)) | Y268: =IF(OR(C268="",H268=""),"",X268-H268)
A269: =IF(C269="","",ROW()-5) | X269: =IF(C269="","",SUM(L269,T269,U269,W269)) | Y269: =IF(OR(C269="",H269=""),"",X269-H269)
A270: =IF(C270="","",ROW()-5) | X270: =IF(C270="","",SUM(L270,T270,U270,W270)) | Y270: =IF(OR(C270="",H270=""),"",X270-H270)
A271: =IF(C271="","",ROW()-5) | X271: =IF(C271="","",SUM(L271,T271,U271,W271)) | Y271: =IF(OR(C271="",H271=""),"",X271-H271)
A272: =IF(C272="","",ROW()-5) | X272: =IF(C272="","",SUM(L272,T272,U272,W272)) | Y272: =IF(OR(C272="",H272=""),"",X272-H272)
A273: =IF(C273="","",ROW()-5) | X273: =IF(C273="","",SUM(L273,T273,U273,W273)) | Y273: =IF(OR(C273="",H273=""),"",X273-H273)
A274: =IF(C274="","",ROW()-5) | X274: =IF(C274="","",SUM(L274,T274,U274,W274)) | Y274: =IF(OR(C274="",H274=""),"",X274-H274)
A275: =IF(C275="","",ROW()-5) | X275: =IF(C275="","",SUM(L275,T275,U275,W275)) | Y275: =IF(OR(C275="",H275=""),"",X275-H275)
A276: =IF(C276="","",ROW()-5) | X276: =IF(C276="","",SUM(L276,T276,U276,W276)) | Y276: =IF(OR(C276="",H276=""),"",X276-H276)
A277: =IF(C277="","",ROW()-5) | X277: =IF(C277="","",SUM(L277,T277,U277,W277)) | Y277: =IF(OR(C277="",H277=""),"",X277-H277)
A278: =IF(C278="","",ROW()-5) | X278: =IF(C278="","",SUM(L278,T278,U278,W278)) | Y278: =IF(OR(C278="",H278=""),"",X278-H278)
... A300: =IF(C300="","",ROW()-5) | X300: =IF(C300="","",SUM(L300,T300,U300,W300)) | Y300: =IF(OR(C300="",H300=""),"",X300-H300)

Sheet ④ 리스크 및 고려사항
A1: 리스크 및 고려사항
A2: 등급은 발생가능성 × 영향도로 자동 산출됩니다. 등급 [최상] 항목은 대응방안·담당·시점을 반드시 기재하십시오.
A4: 리스크 ID | B4: 구분 | C4: 리스크명 | D4: 상세 내용 | E4: 관련 근거 (요구사항 ID 등) | F4: 발생가능성 | G4: 영향도 | H4: 등급 (자동) | I4: 대응전략 | J4: 대응방안 | K4: 담당 | L4: 대응 시점 | M4: 상태
A7: =IF(C7="","","R-"&TEXT(ROW()-4,"00"))
A8: =IF(C8="","","R-"&TEXT(ROW()-4,"00"))
A9: =IF(C9="","","R-"&TEXT(ROW()-4,"00"))
A10: =IF(C10="","","R-"&TEXT(ROW()-4,"00"))
A11: =IF(C11="","","R-"&TEXT(ROW()-4,"00"))
A12: =IF(C12="","","R-"&TEXT(ROW()-4,"00"))
A13: =IF(C13="","","R-"&TEXT(ROW()-4,"00"))
A14: =IF(C14="","","R-"&TEXT(ROW()-4,"00"))
A15: =IF(C15="","","R-"&TEXT(ROW()-4,"00"))
A16: =IF(C16="","","R-"&TEXT(ROW()-4,"00"))
A17: =IF(C17="","","R-"&TEXT(ROW()-4,"00"))
A18: =IF(C18="","","R-"&TEXT(ROW()-4,"00"))
... A54: =IF(C54="","","R-"&TEXT(ROW()-4,"00"))

Sheet ⑤ 확인사항·질의
A1: 발주기관 확인사항 · 질의
A2: 공공 입찰은 제안 질의 마감일이 별도로 존재합니다. 시급도 [최우선] 항목은 반드시 공식 질의로 서면 회신을 확보하십시오.
A4: 확인 ID | B4: 구분 | C4: 확인사항 | D4: 배경 · 근거 | E4: 미확정 시 영향 | F4: 확인 채널 | G4: 시급도 | H4: 상태 | I4: 질의 제출일 | J4: 회신 내용 요약 | K4: 담당
A7: =IF(C7="","","Q-"&TEXT(ROW()-4,"00"))
A8: =IF(C8="","","Q-"&TEXT(ROW()-4,"00"))
A9: =IF(C9="","","Q-"&TEXT(ROW()-4,"00"))
A10: =IF(C10="","","Q-"&TEXT(ROW()-4,"00"))
A11: =IF(C11="","","Q-"&TEXT(ROW()-4,"00"))
A12: =IF(C12="","","Q-"&TEXT(ROW()-4,"00"))
A13: =IF(C13="","","Q-"&TEXT(ROW()-4,"00"))
A14: =IF(C14="","","Q-"&TEXT(ROW()-4,"00"))
A15: =IF(C15="","","Q-"&TEXT(ROW()-4,"00"))
A16: =IF(C16="","","Q-"&TEXT(ROW()-4,"00"))
A17: =IF(C17="","","Q-"&TEXT(ROW()-4,"00"))
A18: =IF(C18="","","Q-"&TEXT(ROW()-4,"00"))
... A54: =IF(C54="","","Q-"&TEXT(ROW()-4,"00"))

Sheet ⑥ 손익 시나리오
B2: 손익 시나리오 ★V2.0 신설
B3: 노란 셀만 입력하십시오. 공수(M/M)는 「③ 요구사항 검토」 및 「① 표지」와 연동되며, 이익률은 「① 표지」 Gate 2 판정에 사용됩니다.
B5: 1. 재원 (입력)
B6: 사업예산 (VAT 별도) | G6: 입찰공고문 추정가격 등
B7: 공제 항목 ① (예: 기술지원 정액 지급) | G7: 파워톡 기술지원비 41,800,000원(VAT 포함) ÷ 1.1 — 낙찰자가 정액 지급
B8: 공제 항목 ② (예: 상용SW 직접구매)
B9: 공제 항목 ③
B10: 가용 재원 | D10: =D6-SUM(D7:D9) -> 0
B12: 2. 원가 (① 표지 4항 부문별 공수·단가 연동)
B13: 인건비 (부문별 합계) | D13: ='① 표지·심의결과'!F38 -> 0 | G13: ① 표지 4항에서 자동 연동
B14: 출장비·상주 비용 | G14: 자체 10.18MM × 3,000,000원 + 외주 12.97MM × 1,000,000원 (연구소 6.5MM은 원격 수행 전제)
B15: 상용SW·라이선스 구매 | G15: 상용 웹오피스 SDK는 견적 미확보 → 3항 미반영 원가로 계상
B16: 인프라·장비 비용 | G16: GPU·서버·개발 PC 등 제안사 부담분
B17: 작업장소 임차·환경 구축 | G17: 상주 개발 사무공간, 회선, 보안환경
B18: 검증·품질 비용 | G18: 성능 검증용 데이터 구축, QA 전담 인력 등
B19: 기타 직접비
B20: 원가 합계 | D20: =SUM(D13:D19) -> 0
B22: 3. 미반영 원가 (추정) — 견적 미확보 항목
B23: 항목 | D23: 최소(원) | E23: 최대(원) | F23: 근거 / 비고
B24: (예시) 상용 솔루션 라이선스 | F24: 제품 미지원(F4) 항목 대응을 위한 상용SW 도입 시 기재
B29: 미반영 원가 합계 | D29: =SUM(D24:D28) -> 0 | E29: =SUM(E24:E28) -> 0
B31: 4. 손익 판정
B32: 이익 (가용재원 − 원가) | D32: =$D$10-$D$20 -> 0
B33: 이익률 | D33: =IFERROR(D32/$D$10,0) -> 0 | G33: → ① 표지 Gate 2 판정에 연동
B34: 미반영 원가 최대 반영 시 이익 | D34: =$D$10-$D$20-$E$29 -> 0
B35: 미반영 원가 최대 반영 시 이익률 | D35: =IFERROR(D34/$D$10,0) -> 0 | G35: → ① 표지 Gate 2 판정에 연동

Sheet ⑦ 작성 가이드
B2: 작성 가이드 (V1.1)
B3: Pre-VRB는 사업 전반을 심의하는 자리가 아니라, 제품으로 해결되지 않는 부분의 개발 공수와 일정을 확정하기 위한 단계입니다.
B5: 1. Pre-VRB 프로세스 및 부서 역할
B6: 단계 | C6: 주관 부서 | D6: 수행 내용 | E6: 산출물
B7: ① Pre-VRB 요청 | C7: 영업부서 (AX서비스사업부 AX서비스영업팀·AX서비스BD팀) | D7: 제안 건 발생 시 인공지능연구소 및 AI사업부문 PMO/PM에 Pre-VRB를 요청. 제안요청서·공고문·고객 협의 내용 공유 | E7: Pre-VRB 요청 (①표지 1항 작성)
B8: ② 요구사항 전사 · 사전산정 | C8: 영업부서 (AX서비스BD팀) | D8: 제안요청서의 시스템·기능 / 성능·품질 / 인터페이스 / 데이터 요구사항을 상세 내용의 단락 단위로 분해하여 「③ 요구사항 검토」에 원문 그대로 기재하고, BD 자체 사전산정 공수를 함께 기재 | E8: ③시트 B~H 컬럼
B9: ③ 제품 적합도 판정 | C9: 제품개발부서 (인공지능연구소) | D9: 각 세부항목이 제품 기본기능으로 해결되는지, 제품 추가개발이 필요한지, 제품 범위 밖(SI 대상)인지를 구분하고 제품 추가개발 공수를 산정 | E9: ③시트 I~M 컬럼
B10: ④ 개발 공수 산정 | C10: 수행부서 (AI사업부문 PM·PMO) | D10: 연구소의 Fit 판정 결과를 검토한 뒤, 제품 외 영역을 제품 활용 개발 / 커스터마이징 신규개발(SI) / 연계 개발로 구분하고 공수를 산정. 자체 인력으로 부족한 부분은 협력업체 외주용역으로 구성 | E10: ③시트 N~T 컬럼
B11: ⑤ 취합·검토의견 제출 | C11: 수행부서 (AI사업부문 PM 주관 · PMO 지원) | D11: 배정된 PM이 연구소의 Fit 판정 결과를 상세 검토하고 제품 외 개발공수 산정 결과를 종합하여 Pre-VRB 검토 의견을 별도 시트 또는 보고서로 제출. PMO는 작성 기준·양식·산정 방법을 가이드하고 결과를 검증 | E11: ①·④·⑤·⑥시트 + PM 검토의견 보고서
B12: ⑥ 제안 여부 결정 | C12: VRB (영업·제안·수행·제품개발부서 합동) | D12: 게이트 판정과 검토 의견을 근거로 제안 참여 여부 및 조건을 결정 | E12: ①표지 5항
B14: 2. 유관 부서 및 역할 정의
B15: 구분 | C15: 부서 | D15: Pre-VRB 역할 | E15: 비고
B16: 영업부서 | C16: AX서비스사업부 AX서비스영업팀 · AX서비스BD팀 | D16: Pre-VRB 요청, 고객·발주처 정보 제공, 제안요청서 요구사항 전사, 발주기관 확인사항 질의 제출 | E16: ③시트 요구사항 전사의 주체
B17: 제안부서 | C17: AX서비스사업부 기획팀 | D17: 제안 전략·일정 수립, 제안서 작성 총괄, 평가 기준 및 제출 요건 관리 | E17: Pre-VRB 결과를 제안 전략에 반영
B18: 수행부서 | C18: AI사업부문 PM · PMO · AI기술팀 · 서비스개발팀 · 데이터구축팀 | D18: 제품 외 개발 공수 산정, 개발 구분 판정, 리스크·확인사항 관리, 손익 산정 및 검토의견 제출. PM이 주도적으로 작성하고 PMO는 산정 기준·양식을 가이드하며 결과를 검증 | E18: 투입 인력 부족 시 협력업체 외주용역으로 구성 — ③시트 '공수 외주·협력사'에 기재
B19: 제품개발부서 | C19: 인공지능연구소 (솔루션개발그룹 · LLM그룹 · KS그룹 · 음성그룹 · 비전그룹 · 자율에이전트그룹) | D19: 제품 적합도(Fit) 판정, 제품 추가개발 범위 및 공수 산정, 제품 로드맵 반영 여부 결정 | E19: 제품별 그룹이 분리되어 있으므로 '담당 그룹' 컬럼에 판정 주체 그룹을 명시
B21: 3. 제품 적합도(Fit) 판정 코드 [인공지능연구소 입력]
B22: 코드 | C22: 의미 | D22: 판정 기준 | E22: 후속 처리
B23: F1 제품 기본기능 | C23: 현행 제품이 그대로 제공 | D23: 별도 개발 없이 현재 제품 버전으로 요구사항 충족 | E23: 연구소 공수 0 / 사업부문은 D5 또는 D1(화면·연계만)
B24: F2 제품 설정·구성 | C24: 제품 설정·파라미터·템플릿으로 대응 | D24: 코드 수정 없이 관리자 설정·구성 작업만으로 충족 | E24: 연구소 공수 0 / 사업부문은 D1 제품 활용 개발
B25: F3 제품 추가개발 | C25: 제품 코어 개선이 필요 | D25: 제품 자체를 개선해야 충족 가능하며 타 고객에도 공통 적용 가치가 있음 | E25: 연구소가 공수 산정 및 제품 로드맵 반영 여부 결정
B26: F4 제품 미지원(SI 대상) | C26: 제품 범위 밖 | D26: 고객 고유 요건이거나 제품 로드맵에 반영할 계획이 없음 | E26: 사업부문이 D2 또는 D3으로 공수 산정
B27: F5 비개발(계약·관리) | C27: 개발 대상이 아님 | D27: 계약조건·보안·품질·관리 요구사항 등 | E27: 사업부문이 D4로 관리 공수만 산정
B29: 4. 개발 구분 코드 [AI사업부문 입력]
B30: 코드 | C30: 의미 | D30: 판정 기준 | E30: 공수 귀속
B31: D1 제품 활용 개발 | C31: 제품 API·기능을 활용한 응용 개발 | D31: 제품이 제공하는 기능 위에 화면·흐름·설정을 구성 | E31: AI사업부문 또는 외주
B32: D2 커스터마이징 신규개발(SI) | C32: 제품과 무관한 신규 개발 | D32: 제품 미지원(F4) 항목을 신규 설계·개발 | E32: AI사업부문 또는 외주
B33: D3 연계 개발 | C33: 외부 시스템 인터페이스 개발 | D33: 타 시스템·타사 제품과의 연동 | E33: AI사업부문 또는 외주
B34: D4 비개발(관리·지원) | C34: 관리·산출물·환경 구성 활동 | D34: PM·품질·보안·인프라 구성 등 | E34: PMO 또는 AI사업부문
B35: D5 해당없음(제품 종결) | C35: 제품 단계에서 종결 | D35: F1 또는 F3으로 제품이 해결하여 SI 공수가 발생하지 않음 | E35: 공수 0
B37: 5. 컬럼별 입력 규칙 [③ 요구사항 검토]
B38: 컬럼 | C38: 담당 | D38: 입력 규칙 | E38: 비고
B39: 요구사항 대분류 | C39: 영업(BD) | D39: 시스템·기능 / 성능·품질 / 인터페이스 / 데이터 / 보안 / 테스트 / 제약 / 프로젝트관리 / 프로젝트지원 | E39: 드롭다운
B40: 요구사항 ID | C40: 영업(BD) | D40: 제안요청서 원문 ID를 그대로 사용 (예: SFR-001). 세부항목이 여러 행이면 동일 ID를 반복 기재 | E40: 요구사항 추적표와 정합성 확보
B41: 세부항목 No. | C41: 영업(BD) | D41: 요구사항 상세 내용의 단락 순번 (1, 2, 3 …) | E41: ★한 단락 = 한 행
B42: 상세 내용 | C42: 영업(BD) | D42: 제안요청서 원문을 요약하지 말고 단락 그대로 전사. 수치·조건은 반드시 포함 | E42: ★판정의 근거가 되므로 임의 해석 금지
B43: 공수 영업(BD) 사전산정 | C43: 영업(BD) | D43: BD가 자체 기준으로 사전 산정한 공수 (M/M). 요구사항 단위 산정이 어려우면 대표 행에 일괄 기재 | E43: ★비교·검증 전용 — 확정 공수 합계에 합산되지 않음
B44: 담당 그룹 | C44: 연구소 | D44: 해당 세부항목의 제품 적합도를 판정한 그룹명. 제품과 무관하면 '해당없음' | E44: 드롭다운 (6개 그룹)
B45: 제품 적합도(Fit) | C45: 연구소 | D45: F1~F5 중 선택 (위 3항 참조) | E45: ★Pre-VRB의 1차 판정
B46: Fit 판정 근거 | C46: 연구소 | D46: 보유 제품·모듈명, 현재 지원 수준, 미지원 사유를 구체적으로 기재
...

Sheet ⑧ 작성 예시
A1: 작성 예시 — 「③ 요구사항 검토」 작성 방법 (한국전력공사 AI 회의록 사업 실사례)
A2: 동일 요구사항(SFR-003)이 세부항목 단위로 어떻게 분해되고, 제품 적합도에 따라 공수 귀속이 어떻게 달라지는지를 보여주는 예시입니다.
A4: 자동 | B4: 영업(BD) | C4: 영업(BD) | D4: 영업(BD) | E4: 영업(BD) | F4: 영업(BD) | G4: 영업(BD) | H4: 영업(BD) | I4: 연구소 | J4: 연구소 | K4: 연구소 | L4: 연구소 | M4: 연구소 | N4: AI사업부문 | O4: AI사업부문 | P4: AI사업부문 | Q4: AI사업부문 | R4: AI사업부문 | S4: AI사업부문 | T4: AI사업부문 | U4: PM·PMO | V4: 자동 | W4: 자동 | X4: PM·PMO | Y4: PM·PMO | Z4: PM·PMO | AA4: PM·PMO
A5: No. | B5: 요구사항 대분류 | C5: 요구사항 ID | D5: 요구사항명 | E5: 세부 항목 No. | F5: 상세 내용 (제안요청서 단락 원문) | G5: 우선 순위 | H5: 공수 영업(BD) 사전산정 | I5: 담당 그룹 | J5: 제품 적합도 (Fit) | K5: Fit 판정 근거 | L5: 공수 연구소 (제품 추가개발) | M5: 제품 반영 계획 | N5: 개발 구분 | O5: 가능 여부 | P5: 난이도 | Q5: 공수 산정 근거 | R5: 공수 AI사업부문 (수행·개발) | S5: 공수 외주·협력사 | T5: 조달 구분 | U5: 공수 PM·PMO | V5: 공수 합계 (확정) | W5: BD 사전산정 대비 증감 | X5: 리스크 ID | Y5: 확인사항 ID | Z5: PM·PMO 종합의견 | AA5: 비고
A6: 1 | B6: 시스템·기능 | C6: SFR-003 | D6: 회의록시스템 - 회의 음성인식 기능 | E6: 1 | F6: 파일 및 스트리밍 기반 준실시간 음성인식(STT) | G6: 상 | H6: 5.5 | I6: 음성그룹 | J6: F1 제품 기본기능 | K6: Konan STT 엔진 보유 — 핵심 기술 자산 | M6: 현행 제품 적용 | N6: D1 제품 활용 개발 | O6: O | P6: 중 | Q6: 제품 STT API 호출 구조로 대응 | T6: 자체수행 | V6: =SUM(L6,R6,S6,U6) -> 0 | W6: =IF(H6="","",V6-H6) -> -5.5
A7: 2 | B7: 시스템·기능 | C7: SFR-003 | D7: 회의록시스템 - 회의 음성인식 기능 | E7: 2 | F7: 다중 음성 포맷 지원 (mp3/wav 등) | G7: 상 | I7: 음성그룹 | J7: F1 제품 기본기능 | K7: 제품 표준 지원 포맷 | M7: 현행 제품 적용 | N7: D5 해당없음(제품 종결) | O7: O | P7: 하 | Q7: 제품 기본기능으로 종결 | T7: 자체수행 | V7: =SUM(L7,R7,S7,U7) -> 0 | W7: =IF(H7="","",V7-H7)
A8: 3 | B8: 시스템·기능 | C8: SFR-003 | D8: 회의록시스템 - 회의 음성인식 기능 | E8: 3 | F8: 메신저형 UI로 인식 결과 표출 | G8: 상 | I8: 솔루션개발그룹 | J8: F1 제품 기본기능 | K8: OnNote 전사 뷰어 보유 | M8: 현행 제품 적용 | N8: D1 제품 활용 개발 | O8: O | P8: 중 | Q8: 제품 뷰어 컴포넌트에 고객 UI 스타일 적용 | S8: 0.1 | T8: 자체수행 | V8: =SUM(L8,R8,S8,U8) -> 0.1 | W8: =IF(H8="","",V8-H8)
A9: 4 | B9: 시스템·기능 | C9: SFR-003 | D9: 회의록시스템 - 회의 음성인식 기능 | E9: 4 | F9: ITN — 숫자·금액·지번의 아라비아 표기 변환 | G9: 상 | I9: 음성그룹 | J9: F3 제품 추가개발 | K9: 기존 ITN 모듈 보유하나 전력·행정 도메인 표기 규칙 개선 필요 | L9: 1 | M9: 제품 로드맵 반영 (공통 개선) | N9: D5 해당없음(제품 종결) | O9: O | P9: 상 | Q9: 연구소 제품 개선으로 종결 — SI 공수 없음 | T9: 자체수행 | V9: =SUM(L9,R9,S9,U9) -> 1 | W9: =IF(H9="","",V9-H9)
A10: 5 | B10: 시스템·기능 | C10: SFR-005 | D10: 회의록시스템 - 회의록 초안 작성 기능 | E10: 4 | F10: 회의유형별 템플릿 자동생성 — 표준서식·문서구조 원문 반영, 레이아웃 100% 유지 | G10: 상 | I10: 솔루션개발그룹 | J10: F4 제품 미지원(SI 대상) | K10: '레이아웃 100% 유지'는 제품 템플릿 엔진 범위 초과 | M10: 제품 반영 계획 없음 | N10: D2 커스터마이징 신규개발(SI) | O10: △ | P10: 상 | Q10: 상용 웹오피스 SDK 연계 기반 템플릿 엔진 신규 개발 | S10: 0.6 | T10: 상용SW 구매 | V10: =SUM(L10,R10,S10,U10) -> 0.6 | W10: =IF(H10="","",V10-H10)
A11: 6 | B11: 시스템·기능 | C11: SFR-005 | D11: 회의록시스템 - 회의록 초안 작성 기능 | E11: 5 | F11: 전용 스크립트 인터페이스 제공 | G11: 상 | I11: 솔루션개발그룹 | J11: F1 제품 기본기능 | K11: 제품 스크립트 뷰 보유 | M11: 현행 제품 적용 | N11: D1 제품 활용 개발 | O11: O | P11: 중 | Q11: 제품 기능 활용 | S11: 0.1 | T11: 상용SW 구매 | V11: =SUM(L11,R11,S11,U11) -> 0.1 | W11: =IF(H11="","",V11-H11)
A12: 7 | B12: 시스템·기능 | C12: SFR-002 | D12: 회의록시스템 - 내부시스템 연계기능 | E12: 1 | F12: 인사정보 연동 — 조직도 동기화, 열람권한 4단계(개인→부서→처실→전사) | G12: 상 | H12: 3 | I12: 솔루션개발그룹 | J12: F4 제품 미지원(SI 대상) | K12: 고객사 고유 인사체계 연동으로 제품 범위 밖 | M12: 제품 반영 계획 없음 | N12: D3 연계 개발 | O12: △ | P12: 상 | Q12: 인사 API 연계 어댑터 + 4단계 권한 모델 신규 설계 | R12: 0.12 | S12: 0.84 | T12: 외주(하도급) | V12: =SUM(L12,R12,S12,U12) -> 0.96 | W12: =IF(H12="","",V12-H12) -> -2.04
A14: [읽는 법]
A15: ① 1~4행은 하나의 요구사항(SFR-003 회의 음성인식 기능)을 세부항목 단위로 나눈 것입니다. 같은 요구사항이라도 세부항목마다 제품 적합도가 다릅니다.
A16: ② 1·2행은 F1(제품 기본기능)이므로 연구소 공수도 0, 사업부문 공수도 0입니다. 제품이 그대로 해결하는 영역입니다.
A17: ③ 4행은 F3(제품 추가개발)이므로 연구소 공수만 1.0MM 발생하고 사업부문 공수는 0입니다. 제품 로드맵에 반영되는 개선입니다.
A18: ④ 5·6행(SFR-005)은 F4(제품 미지원)이므로 연구소 공수는 0이고 사업부문·외주 공수가 발생합니다. 커스터마이징 신규개발(SI) 영역입니다.
A19: ⑤ 7행(SFR-002)은 타 시스템 연동으로 D3(연계 개발)에 해당하며, 자체 0.12MM + 외주 0.84MM으로 나누어 산정했습니다.

Sheet ⑨ 변동사항(타 작성본 비교)
A1: 타 작성본(Pre-VRB … v0.1_260921) 대비 변동사항
A2: 노란색(FFFF00) 셀 = 타 작성본과 내용이 다른 셀 (각 셀 메모에 타 작성본 내용 기재). 서식(o기호·줄바꿈·공백) 차이는 제외. 양식 기본 입력셀의 연노랑(FFF2CC)과 구분됩니다.
A3: ※ 공통 참고: 타 작성본은 「RFP 초안」 기준(예산·입찰방식 미기재, 일반경쟁)이며, Claude 작성본은 수령 PDF(제한경쟁, 894,116,348원) 기준입니다. 또한 타 작성본은 양식 V2.0(③시트 공수 컬럼 Q~U 신설, ③-1 비율 산정 시트 추가)을 사용합니다.
A5: No | B5: 시트 | C5: 셀 | D5: 구분 | E5: Claude 작성본 | F5: 타 작성본(v0.1) | G5: 비고
A6: 1 | B6: ③ 요구사항 검토 | C6: F29 | D6: ③ 상세내용 차이 | E6: ◦ 업무 수행 시 사용자의 데이터·지식 및 시스템 접근권한을 준수하여야 하며, 업무 특성상 필요한 경우 사용자의 확인·승인을 거쳐 후속 업무가 수행될 수 있도록 구현하여야 함 ※ 업무별 특화 AI Agent 구현 예시 │ Agent 예시 │ 주요 구현내용 │ 법률자문 업무지원 Agent │ ▪ 사내·외 법률자문 자료와 외부 법령정보 API를 활용하여 관련 정보를 검색·분석하고 법률자문 답변 초안을 지정된 HWP 양식으로 생성·전달 │ 전자결재 문서검색·분석 Agent │ ▪ 사용자의 문서 조회권한 범위 내에서 관련 전자결재 문서를 검색·요약하고 문서번호·제목 등 주요 정보와 원문을 일괄 제공 │ 공사설계 업무지원 Agent │ ▪ 표준품셈, 노임단가, 제경비, 물가정보 등 내·외부 데이터를 활용하여 필요 정보를 검색·분석·산출하고 설계서 초안을 지정된 형식으로 생성 │ AI 회의록 Agent │ ▪ 회의 음성을 STT로 변환·분석하여 주요 논의·결정·조치사항을 정리하고 회의록을 지정된 HWP 양식으로 생성·전달 - 상기 사례는 AI Agent의 구현 수준 및 방향에 대한 예시이며 실제 구축 대상업무 및 세부 구현범위는 현업 요구사항 분석 등을 통해 발주기관과 협의하여 확정한다. | F6: [4] 업무 수행 시 사용자의 데이터·지식 및 시스템 접근권한을 준수하여야 하며, 업무 특성상 필요한 경우 사용자의 확인·승인을 거쳐 후속 업무가 수행될 수 있도록 구현하여야 함 | G6: 타 자료는 Agent 구현 예시 표(※)를 별도 세부항목(5번)으로 분리. Claude 자료는 4번 항목 하위로 포함(표는 o로 시작하지 않으므로 분할 안 함)
A7: 2 | B7: ③ 요구사항 검토 | C7: C26 | D7: ③ 세부항목 수 차이 | E7: 4 | F7: 5 | G7: 타 자료는 Agent 구현 예시 표(※)를 별도 세부항목(5번)으로 분리. Claude 자료는 4번 항목 하위로 포함(표는 o로 시작하지 않으므로 분할 안 함)
A8: 3 | B8: ③ 요구사항 검토 | C8: F148 | D8: ③ 상세내용 차이 | E8: ◦ 본 사업을 효과적으로 수행하기 위한 추진조직 및 지원조직 구성계획을 명확하게 제시하여야 함 | F8: [1] 본 사업을 효과적으로 수행하기 위한 추진조직 및 지원조직 구성계획을 | G8: 타 자료는 1번 문장을 줄바꿈 위치에서 두 행(1·2번)으로 잘못 분할 → 이후 번호가 1씩 밀림(총 5개). 원문 기준 o 항목은 4개
A9: 4 | B9: ③ 요구사항 검토 | C9: F149 | D9: ③ 상세내용 차이 | E9: ◦ 사업관리자(PM)는 반드시 주사업자 소속으로 일정 수준 이상 직급의 직원으로서 본 사업을 총괄할 수 있는 경험이 있는 전문 인력이어야 하며, 사업기간 동안 상주가 가능하여야 함 | F9: [2] 명확하게 제시하여야 함 | G9: 타 자료는 1번 문장을 줄바꿈 위치에서 두 행(1·2번)으로 잘못 분할 → 이후 번호가 1씩 밀림(총 5개). 원문 기준 o 항목은 4개
A10: 5 | B10: ③ 요구사항 검토 | C10: F150 | D10: ③ 상세내용 차이 | E10: ◦ 인력교체 필요 시 인력교체 전에 대체인력을 투입하여야 하며, 인력교체기간 동안 발생하는 업무의 안정화 및 품질저하 방지 대책을 제시하여야 함 | F10: [3] 사업관리자(PM)는 반드시 주사업자 소속으로 일정 수준 이상 직급의 직원으로서 본 사업을 총괄할 수 있는 경험이 있는 전문 인력이어야 하며, 사업기간 동안 상주가 가능하여야 함 | G10: 타 자료는 1번 문장을 줄바꿈 위치에서 두 행(1·2번)으로 잘못 분할 → 이후 번호가 1씩 밀림(총 5개). 원문 기준 o 항목은 4개
A11: 6 | B11: ③ 요구사항 검토 | C11: F151 | D11: ③ 상세내용 차이 | E11: ◦ 사업 수행조직 외 본 사업을 성공적으로 수행할 수 있도록 지원 또는 자문 조직의 구성을 제시할 수 있음 | F11: [4] 인력교체 필요 시 인력교체 전에 대체인력을 투입하여야 하며, 인력교체기간 동안 발생하는 업무의 안정화 및 품질저하 방지 대책을 제시하여야 함 | G11: 타 자료는 1번 문장을 줄바꿈 위치에서 두 행(1·2번)으로 잘못 분할 → 이후 번호가 1씩 밀림(총 5개). 원문 기준 o 항목은 4개
A12: 7 | B12: ③ 요구사항 검토 | C12: C148 | D12: ③ 세부항목 수 차이 | E12: 4 | F12: 5 | G12: 타 자료는 1번 문장을 줄바꿈 위치에서 두 행(1·2번)으로 잘못 분할 → 이후 번호가 1씩 밀림(총 5개). 원문 기준 o 항목은 4개
A13: 8 | B13: ③ 요구사항 검토 | C13: F166 | D13: ③ 상세내용 차이 | E13: ◦ 원활한 사업추진을 위해 보고회를 개최하여야 하며, 보고 시 도출된 문제점은 즉시 수정 보완하여야 한다. │ 구 분 │ 보고명 │ 보고내용 │ 시 기 │ 정기보고 │ 주간보고 │ - 진도관리(계획대비 실적) / - 문제점 보고 및 특이사항 / - 진척률 및 차주계획 │ 매주 (협의결정) │ 비정기보고 │ 착수보고 │ - 사업 추진전략 및 세부 진행계획 보고 / - 업무분장 및 협조사항 요청 │ 협의 │ │ 중간보고 │ - 개발상황 및 현안 보고 │ │ │ 완료보고 │ - 개발결과 보고 │ │ │ 수시보고 │ - 이슈사항 및 문제점 협의 등 │ | F13: [1] 원활한 사업추진을 위해 보고회를 개최하여야 하며, 보고 시 도출된 문제점은 즉시 수정 보완하여야 한다. | G13: 타 자료는 보고 체계 표를 별도 세부항목(2번)으로 분리. Claude 자료는 1번 항목 하위로 포함
A14: 9 | B14: ③ 요구사항 검토 | C14: C166 | D14: ③ 세부항목 수 차이 | E14: 1 | F14: 2 | G14: 타 자료는 보고 체계 표를 별도 세부항목(2번)으로 분리. Claude 자료는 1번 항목 하위로 포함
A15: 10 | B15: ③ 요구사항 검토 | C15: F167 | D15: ③ 상세내용 차이 | E15: ◦ 각 산출물은 해당 단계에 따라 제출하여야 함 │ 구 분 │ 시 기 │ 수 량 │ 착수계, 착수보고서 │ 계약 후 10일 이내 │ 1부 │ 사업수행 계획서 │ 계약 후 10일 이내 │ 1부 │ 보안서약서(대표, 투입인력) │ 계약 후 10일 이내 │ 대상자별 1부 │ 개인정보 수집·이용 동의서 │ 계약 후 10일 이내 │ 각1부 │ 요구사항 정의/분석서 │ 별도협의 │ 1부 │ 시스템 구성도 및 AI 서비스 아키텍처 │ 설계 완료 후 │ 1부 │ 시스템·API 연계 설계서 │ 설계 완료 후 │ 1부 │ 업무별 특화 AI Agent 설계서 │ 설계 완료 후 │ 1부 │ MCP Gateway 및 Tool 연계 명세서 │ 설계 완료 후 │ 1부 │ RAG 지식데이터 구축·처리 내역서 │ 구축 완료 후 │ 1부 │ 테스트 계획서 │ 테스트 전 │ 1부 │ 테스트 결과서 │ 테스트 완료 후 │ 1부 │ AI 서비스 성능·품질 검증 결과서 │ 테스트 완료 후 │ 1부 │ NPU 기반 음성 AI 성능검증·실증 결과서 │ 테스트 완료 후 │ 1부 │ 취약점 조치결과 보고서 │ 조치 완료 후 │ 1부 │ 작업진척 보고서 │ 주간 또는 수시 │ - │ 회의록·업무협의서 │ 발생 시 │ - │ 완료(최종)보고서 │ 최종 완료 시 │ 1부 │ 관리자 지침서(설치, 운영 등) 및 교육교재(매뉴얼) │ 최종 완료 시 │ 1부 ※ 기타 표기되지 않은 산출물은 제안요청 또는 계약상대자 제안서 내용을 근거로 제출하여야 한다. (별도 협의) ※ 산출물의 세부 구성과 제출시기는 사업수행 과정에서 발주기관과 협의하여 조정할 수 있으며 사업수행에 따른 변경사항을 반영하여 시스템 구성도, AI 서비스 아키텍처, 시스템 간 연계구성 등 주요 기술문서를 최종 현행호하여 제출하여야 함 | F15: [1] 각 산출물은 해당 단계에 따라 제출하여야 함 | G15: 타 자료는 산출물 표를 별도 세부항목(2번)으로 분리했으며, 표 내용이 수령 PDF와 다름(RPA 스크립트 목록·성과측정 결과 분석보고서 등 포함, AI Agent 설계서·MCP 명세서 등 없음) → RFP 초안과 본 RFP 버전 차이로 추정
A16: 11 | B16: ③ 요구사항 검토 | C16: C167 | D16: ③ 세부항목 수 차이 | E16: 1 | F16: 2 | G16: 타 자료는 산출물 표를 별도 세부항목(2번)으로 분리했으며, 표 내용이 수령 PDF와 다름(RPA 스크립트 목록·성과측정 결과 분석보고서 등 포함, AI Agent 설계서·MCP 명세서 등 없음) → RFP 초안과 본 RFP 버전 차이로 추정
A17: 12 | B17: ③ 요구사항 검토 | C17: F212 | D17: ③ 상세내용 차이 | E17: ◦ 시스템의 결함 및 S/W 개발, 설치 등의 하자가 발견될 경우 즉시 필요한 조치를 취하여 문제를 해결하여야 함 - 하자보수 기간 중 치명적인 하자 및 오류로 인하여 시스템 사용이 불가 시 즉시 개발인력을 투입하여 지원하도록 함 | F17: [3] 시스템의 결함 및 S/W 개발, 설치 등의 하자가 발견될 경우 즉시 필요한 조치를 취하여 문제를 해결하여야 함 - 하자보수 기간 중 치명적인 하자 및 오류로 인하여 시스템 사용이 불가 시 | G17: 타 자료는 3번 항목의 '-' 하위문장을 줄바꿈 위치에서 잘라 별도 행(4번)으로 분리 → 이후 번호가 1씩 밀림(총 9개). 원문 기준 o 항목은 8개
... A31: 26 | B31: ③ 요구사항 검토 | C31: C218 | D31: ③ 세부항목 수 차이 | E31: 7 | F31: 4 | G31: 타 자료 COR-001은 4개 항목이며 문구가 수령 PDF와 다름('자동화 수행', '자동화 스크립트 작성기법' 등) → RFP 초안과 본 RFP 버전 차이로 추정. 수령 PDF 기준 o 항목은 7개
A32: 27 | B32: ① 표지·심의결과 | C32: B2 | D32: 값 차이 | E32: Pre-VRB 공통시트 V1.1 [배포용 템플릿] | F32: [기능] Pre-VRB 공통시트 — 한국남부발전 실행형 AI 플랫폼 구축 용역 [서식 V2.0]
A33: 28 | B33: ① 표지·심의결과 | C33: C7 | D33: 값 차이 | E33: AI 인프라 및 생성형 AI 구축 사업 | F33: 실행형 AI 플랫폼 구축 용역
A34: 29 | B34: ① 표지·심의결과 | C34: E7 | D34: 값 차이 | E34: 신용보증재단중앙회 (발주부서: AI디지털전환부) | F34: 한국남부발전(주) AI전략부 (담당: 김영재 / 070-7713-8642)
A35: 30 | B35: ① 표지·심의결과 | C35: C8 | D35: 값 차이 | E35: 공공 SI — 패키지SW 도입 및 커스터마이징 | F35: 공공 SW 구축 용역 (생성형 AI 플랫폼·서비스 고도화, RAG 지식검색 고도화, NPU 기반 음성 AI 구축)
A36: 31 | B36: ① 표지·심의결과 | C36: E8 | D36: 값 차이 | E36: 경쟁입찰 / 협상에의한계약 | F36: 일반경쟁 입찰(협상에 의한 계약) — RFP 초안 Ⅰ-1 기재. 공동수급·기업규모 제한 등 세부 조건은 초안에 없음(Ⅳ·Ⅴ장 부재)
A37: 32 | B37: ① 표지·심의결과 | C37: C9 | D37: 값 차이 | E37: 617500000 | F37: RFP 초안 미기재(000,000,000원으로 표기) — 본공고 확정 후 반영
A38: 33 | B38: ① 표지·심의결과 | C38: E9 | D38: 값 차이 | E38: 계약체결일로부터7개월 | F38: 계약 체결일로부터 6개월 (RFP 초안 Ⅰ-1)
A39: 34 | B39: ① 표지·심의결과 | C39: C10 | D39: 값 차이 | E39: 2026-10-00 | F39: RFP 초안 단계 — 본공고 미공고
A40: 35 | B40: ① 표지·심의결과 | C40: E10 | D40: 값 차이 | E40: 공고문 미명시 — 확인 필요 | F40: RFP 초안 미기재 — 본공고 확정 후 반영
A41: 36 | B41: ① 표지·심의결과 | C41: C11 | D41: 값 차이 | E41: 2026-10-00 (0) 00:00 | F41: RFP 초안 미기재 — 본공고 확정 후 반영
A42: 37 | B42: ① 표지·심의결과 | C42: E11 | D42: 값 차이 | E42: 2026-10-00 (0) 00:00 | F42: RFP 초안 미기재 — 본공고 확정 후 반영
A43: 38 | B43: ① 표지·심의결과 | C43: C12 | D43: 값 차이 | E43: 협상에의한계약(기술능력평가분야배점한도의 85%이상인 자) | F43: 협상에 의한 계약 — 기술평가 기준·협상적격 점수는 RFP 초안 미기재 — 본공고 확정 후 반영
A44: 39 | B44: ① 표지·심의결과 | C44: E12 | D44: 값 차이 | E44: 기술 90 : 가격 10 | F44: RFP 초안 미기재 — 본공고 확정 후 반영
A45: 40 | B45: ① 표지·심의결과 | C45: C13 | D45: 값 차이 | E45: AX서비스사업부 AX서비스영업팀 김산 이사대우
A46: 41 | B46: ① 표지·심의결과 | C46: E13 | D46: 값 차이 | F46: PM팀 김진서 부장
A47: 42 | B47: ① 표지·심의결과 | C47: E14 | D47: 값 차이 | E47: AI사업부문 사업관리그룹 송승현 부장 / 송인성 부장
A48: 43 | B48: ① 표지·심의결과 | C48: C15 | D48: 값 차이 | E48: 중
A49: 44 | B49: ① 표지·심의결과 | C49: E15 | D49: 값 차이 | E49: 주사업자 사업 참여나 고객과 사전에 과업에 대한 범위가 조정 되었고, GPU 서버 납기로 개발이 제한됨
A50: 45 | B50: ① 표지·심의결과 | C50: B31 | D50: 값 차이 | F50: 제품 활용률 (F1+F2+F3)
A51: 46 | B51: ① 표지·심의결과 | C51: C31 | D51: 수식/양식 구조 차이 | F51: (수식) =TEXT('③-1 비율 산정'!D26,"0.0%")&" (즉시대응 "&TEXT('③-1 비율 산정'!D27,"0.0%")&")" | G51: 양식 V2.0 차이
A52: 47 | B52: ① 표지·심의결과 | C52: D31 | D52: 값 차이 | F52: 개발 구분 비율 (D1/D2/D3)
A53: 48 | B53: ① 표지·심의결과 | C53: E31 | D53: 수식/양식 구조 차이 | F53: (수식) =TEXT('③-1 비율 산정'!G33,"0.0%")&" / "&TEXT('③-1 비율 산정'!G34,"0.0%")&" / "&TEXT('③-1 비율 산정'!G35,"0.0%")&" (공수 기준)" | G53: 양식 V2.0 차이
A54: 49 | B54: ① 표지·심의결과 | C54: C34 | D54: 수식/양식 구조 차이 | E54: (수식) =SUM('③ 요구사항 검토'!T6:T300) | F54: (수식) =SUM('③ 요구사항 검토'!Q6:Q268)+SUM('③ 요구사항 검토'!R6:R268)+SUM('③ 요구사항 검토'!T6:T268) | G54: 양식 V2.0 차이
...
